Workbook

Sheet DATA - IKKE RØR
A1: Description | B1: MGRS | F1: latlon | H1: moh | I1: km from firing pos.
B2: zone | C2: longitude | D2: east | E2: north | F2: east | G2: north | L2: Weather format | M2: Angle of fire
A3: CM pos. Setermoen | B3: 34W | C3: CB | D3: 95097 | E3: 34281 | F3: 68,8 | G3: 18,4 | H3: 625,9 | I3: 4,25 | L3: METCM | M3: High
A4: CM pos. Andøya | B4: 33W | C4: WS | D4: 27868 | E4: 65671 | F4: 69.1 | G4: 15.7 | H4: 23.9 | I4: 4.49 | L4: METCM (from METGM) | M4: Low
A5: CM pos. Harstad | B5: 33W | C5: WS | D5: 63526 | E5: 36578 | F5: 68.8332 | G5: 16.5766 | H5: 75.6 | I5: 29.96 | L5: METCM (from METGC)
A6: N/A | H6: 0 | I6: 0 | L6: METGC
A7: Firing pos. Setermoen | B7: 34W | C7: CB | D7: 91770 | E7: 36941 | F7: 68.822556 | G7: 18.314766 | H7: 314,3 | I7: 0 | L7: METGM
A8: Firing pos. Andøya | B8: 33W | C8: WS | D8: 27048 | E8: 70095 | F8: 69.1397568 | G8: 15.6806463 | H8: 2.3 | I8: 0 | L8: ICAO
A9: Firing pos. Harstad | B9: 33W | C9: WS | D9: 83941 | E9: 14233 | F9: 68.6274734 | G9: 17.0642882 | H9: 657.5 | I9: 0
A10: N/A | H10: 0 | I10: 0
A11: AA0001 | B11: 34W | C11: CB | D11: 98876 | E11: 29642 | F11: 68.759847 | G11: 18.498222 | H11: 378.3 | I11: 10,15
A12: AA0002 | B12: 34W | C12: DB | D12: 05772 | E12: 22520 | F12: 68.698456 | G12: 18.675317 | H12: 268,2 | I12: 20,03
A13: AA0003 | B13: 34W | C13: DB | D13: 13768 | E13: 14375 | F13: 68.628049 | G13: 18.87933 | H13: 643,1 | I13: 31,4
A14: AA0004 | B14: 34W | C14: DB | D14: 19721 | E14: 08136 | F14: 68.573902 | G14: 19.030525 | H14: 862,6 | I14: 40
A15: BB0001 | B15: 33W | C15: WS | D15: 28847 | E15: 60247 | F15: 69.0512567 | G15: 15.7229823 | H15: 256.6 | I15: 9.98
A16: BB0002 | B16: 33W | C16: WS | D16: 30732 | E16: 49925 | F16: 68.9584923 | G16: 15.7670021 | H16: 2 | I16: 20.34
A17: BB0003 | B17: 33W | C17: WS | D17: 32453 | E17: 40501 | F17: 68.8737840 | G17: 15.8068463 | H17: 283.8 | I17: 30 | L17: Target type | M17: Target subtype
A18: CC0001 | B18: 33W | C18: WR | D18: 97859 | E18: 93457 | F18: 68.4367712 | G18: 17.3864176 | H18: 29.2 | I18: 24.93 | J18: Flystripe | L18: Terrain Features | M18: Landing strip
A19: CC0002 | B19: 33W | C19: XR | D19: 00090 | E19: 94111 | F19: 68.4418522 | G19: 17.4413815 | H19: 44.3 | I19: 25.72 | J19: Togbane | L19: Terrain Features | M19: Railroad
A20: CC0003 | B20: 33W | C20: WR | D20: 99459 | E20: 92573 | F20: 68.4282947 | G20: 17.4245494 | H20: 3.4 | I20: 26.56 | J20: Havn | L20: Vehicles | M20: Boats
A41: Gamle mål (backup ved behov)
A42: BB0001 | B42: 34W | C42: CB | D42: 84795 | E42: 29726 | F42: 68.7551 | G42: 18.150281 | H42: 253,8 | I42: 10
A43: BB0002 | B43: 33W | C43: XS | D43: 20957 | E43: 22482 | F43: 68.687773 | G43: 17.983119 | H43: 201,5 | I43: 20,1
A44: BB0003 | B44: 33W | C44: XS | D44: 14334 | E44: 15031 | F44: 68.623835 | G44: 17.81164 | H44: 1079,9 | I44: 30
A45: BB0004 | B45: 33W | C45: XS | D45: 08373 | E45: 06954 | F45: 68.553846 | G45: 17.656676 | H45: 184,3 | I45: 40
A46: CC0001 | B46: 34W | C46: CB | D46: 84341 | E46: 43689 | F46: 68.879986 | G46: 18.122895 | H46: 339,4 | I46: 10
A47: CC0002 | B47: 33W | C47: XS | D47: 17500 | E47: 50176 | F47: 68.937309 | G47: 17.930542 | H47: 794,3 | I47: 20
A48: CC0003 | B48: 33W | C48: XS | D48: 09468 | E48: 56196 | F48: 68.994551 | G48: 17.737209 | H48: 364,8 | I48: 30
A49: CC0004 | B49: 33W | C49: XS | D49: 00844 | E49: 62610 | F49: 69.055331 | G49: 17.528447 | H49: 68,7 | I49: 40,7

Sheet ICAO "no weather"
A1: Test ID | B1: Firing pos. | C1: Weather pos. | D1: Angle of fire | E1: Weather format | F1: Target name | G1: Timestamps | I1: Measured alt. | J1: missdistance
G2: Weather DTG | H2: Fire DTG | J2: range | K2: cross
A3: 1 | B3: N/A | C3: N/A | D3: High | E3: ICAO | F3: AA0001 | G3: 310000Z JUL 03 | H3: 090636Z APR 26 | I3: 31000 | J3: 52.635021 | K3: 20.784626
A4: 2 | F4: AA0001 | H4: 090706Z APR 26 | J4: 52.635021 | K4: 20.784626
A5: 3 | F5: AA0001 | H5: 090906Z APR 26 | J5: 52.635021 | K5: 20.784626
A6: 4 | D6: Low | F6: AA0001 | H6: 090636Z APR 26 | J6: 52.635021 | K6: 20.784626
A7: 5 | F7: AA0001 | H7: 090706Z APR 26 | J7: 52.635021 | K7: 20.784626
A8: 6 | F8: AA0001 | H8: 090906Z APR 26 | J8: 52.635021 | K8: 20.784626
A9: 7 | F9: AA0002 | H9: 090636Z APR 26 | J9: 133.44621 | K9: 27.576827
A10: 8 | F10: AA0002 | H10: 090706Z APR 26 | J10: 133.44621 | K10: 27.576827
A11: 9 | F11: AA0002 | H11: 090906Z APR 26 | J11: 133.44621 | K11: 27.576827
A12: 10 | F12: AA0003 | H12: 090636Z APR 26 | J12: 246,855840 | K12: 37.100398
A13: 11 | F13: AA0003 | H13: 090706Z APR 26 | J13: 246,855840 | K13: 37.100398
A14: 12 | F14: AA0003 | H14: 090906Z APR 26 | J14: 246,855840 | K14: 37.100398

Sheet METCM (Meteomatics)
A1: Test ID | B1: Firing pos. | C1: Weather pos. | D1: Angle of fire | E1: Weather format | F1: Target name | G1: Timestamps | I1: Measured alt. | J1: missdistance
G2: Weather DTG | H2: Fire DTG | J2: range | K2: cross
A3: 13 | B3: Firing pos. Setermoen | C3: CM pos. Setermoen | D3: Low | E3: METCM | F3: AA0001 | G3: 100718Z APR 26 | H3: 100748Z APR 26 | I3: 2000 | J3: 62.280629 | K3: 21.722373
A4: 14 | F4: AA0001 | H4: 100818Z APR 26 | J4: 62.525543 | K4: 21.735085
A5: 15 | F5: AA0001 | H5: 101018Z APR 26 | J5: 63.492964 | K5: 21.785081
A6: 16 | F6: AA0002 | H6: 100748Z APR 26 | J6: 59.381088 | K6: 27.508768
A7: 17 | F7: AA0002 | H7: 100818Z APR 26 | J7: 64.794678 | K7: 27.678511
A8: 18 | F8: AA0002 | H8: 101018Z APR 26 | J8: 82.84702 | K8: 28.209494
A9: 19 | F9: AA0003 | H9: 100748Z APR 26 | J9: 91.145002 | K9: 36.49177
A10: 20 | F10: AA0003 | H10: 100818Z APR 26 | J10: 103.37136 | K10: 36.554296
A11: 21 | F11: AA0003 | H11: 101018Z APR 26 | J11: 142.09692 | K11: 36.75167
A12: 22 | B12: Firing pos. Setermoen | C12: CM pos. Setermoen | D12: Low | E12: METCM | F12: AA0001 | G12: 130924Z APR 26 | H12: 130954Z APR 26 | I12: 3000 | J12: 84.827497 | K12: 23.875684
A13: 23 | F13: AA0001 | H13: 131024Z APR 26 | J13: 85.013829 | K13: 23.889362
A14: 24 | F14: AA0001 | H14: 131224Z APR 26 | J14: 85.754196 | K14: 23.943683
A15: 25 | F15: AA0002 | H15: 130954Z APR 26 | J15: 318.82925 | K15: 45.484355
A16: 26 | F16: AA0002 | H16: 131024Z APR 26 | J16: 319.86606 | K16: 45.550567
A17: 27 | F17: AA0002 | H17: 131224Z APR 26 | J17: 323.9795 | K17: 45.813005
A18: 28 | F18: AA0003 | H18: 130954Z APR 26 | J18: 597.76407 | K18: 51.788044
A19: 29 | F19: AA0003 | H19: 131024Z APR 26 | J19: 599.75275 | K19: 51.847251
A20: 30 | F20: AA0003 | H20: 131224Z APR 26 | J20: 607.64216 | K20: 52.082101
A21: 31 | B21: Firing pos. Setermoen | C21: CM pos. Setermoen | D21: Low | E21: METCM | F21: AA0001 | G21: 140612Z APR 26 | H21: 140642Z APR 26 | I21: 3000 | J21: 58.525761 | K21: 21.500603
A22: 32 | F22: AA0001 | H22: 140712Z APR 26 | J22: 58.789791 | K22: 21.514359
A23: 33 | F23: AA0001 | H23: 140912Z APR 26 | J23: 59.829966 | K23: 21.568153
A24: 34 | F24: AA0002 | H24: 140642Z APR 26 | J24: 184.13257 | K24: 32.408742
A25: 35 | F25: AA0002 | H25: 140712Z APR 26 | J25: 52.190183 | K25: 27.329618
A26: 36 | F26: AA0002 | H26: 140912Z APR 26 | J26: 73.8312 | K26: 28.229607
A27: 37 | F27: AA0003 | H27: 140642Z APR 26 | J27: 342.76612 | K27: 40.881839
A28: 38 | F28: AA0003 | H28: 140712Z APR 26 | J28: 73.999869 | K28: 36.575939
A29: 39 | F29: AA0003 | H29: 140912Z APR 26 | J29: 122.71652 | K29: 37.319748
A30: 40 | B30: Firing pos. Setermoen | C30: CM pos. Setermoen | D30: Low | E30: METCM | F30: AA0001 | G30: 150606Z APR 26 | H30: 150636Z APR 26 | I30: 3000 | J30: 61.977489 | K30: 22.09284
A31: 41 | F31: AA0001 | H31: 150706Z APR 26 | J31: 62.253609 | K31: 22.113371
A32: 42 | F32: AA0001 | H32: 150906Z APR 26 | J32: 63.3406 | K32: 22.19382
A33: 43 | F33: AA0002 | H33: 150636Z APR 26 | J33: 177.55191 | K33: 34.03981
A34: 44 | F34: AA0002 | H34: 150706Z APR 26 | J34: 179.41165 | K34: 34.136237
A35: 45 | F35: AA0002 | H35: 150906Z APR 26 | J35: 186.66154 | K35: 34.512331
A36: 46 | F36: AA0003 | H36: 150636Z APR 26 | J36: 328.29156 | K36: 42.631488
A37: 47 | F37: AA0003 | H37: 150706Z APR 26 | J37: 331.9031 | K37: 42.720989
A38: 48 | F38: AA0003 | H38: 150906Z APR 26 | J38: 345.97092 | K38: 43.07069
A39: 49 | B39: Firing pos. Setermoen | C39: CM pos. Setermoen | D39: Low | E39: METCM | F39: AA0001 | G39: 160606Z APR 26 | H39: 160636Z APR 26 | I39: 3000 | J39: 57.212381 | K39: 20.834326
A40: 50 | F40: AA0001 | H40: 160706Z APR 26 | J40: 57.435789 | K40: 20.836271
...

Sheet METCM (from METGM)
A1: Test ID | B1: Firing pos. | C1: Weather pos. | D1: Angle of fire | E1: Weather format | F1: Target name | G1: Timestamps | I1: Measured alt. | J1: missdistance
G2: Weather DTG | H2: Fire DTG | J2: range | K2: cross
A3: 190 | B3: Firing pos. Setermoen | C3: CM pos. Setermoen | D3: Low | E3: METCM (from METGM) | F3: AA0001 | G3: 060600Z MAY 26 | H3: 060630Z MAY 26 | I3: 15990 | J3: 60.19674 | K3: 20.852029
A4: 191 | F4: AA0001 | H4: 060700Z MAY 26 | J4: 58.248896 | K4: 20.836358
A5: 192 | F5: AA0001 | H5: 060900Z MAY 26 | J5: 47.526879 | K5: 20.732423
A6: 193 | F6: AA0002 | H6: 060630Z MAY 26 | J6: 199.71337 | K6: 31.287796
A7: 194 | F7: AA0002 | H7: 060700Z MAY 26 | J7: 184.34514 | K7: 30.852485
A8: 195 | F8: AA0002 | H8: 060900Z MAY 26 | J8: 71.547763 | K8: 27.802612
A9: 196 | F9: AA0003 | H9: 060630Z MAY 26 | J9: 375.30498 | K9: 44.098872
A10: 197 | F10: AA0003 | H10: 060700Z MAY 26 | J10: 345.39569 | K10: 43.32307
A11: 198 | F11: AA0003 | H11: 060900Z MAY 26 | J11: 119.0736 | K11: 37.793717
A12: 199 | B12: Firing pos. Setermoen | C12: CM pos. Setermoen | D12: Low | E12: METCM (from METGM) | F12: AA0001 | G12: 130924Z APR 26 | H12: 070630Z MAY 26 | I12: 15990 | J12: 58.819638 | K12: 21.042119
A13: 200 | F13: AA0001 | H13: 070700Z MAY 26 | J13: 59.047348 | K13: 21.046798
A14: 201 | F14: AA0001 | H14: 070900Z MAY 26 | J14: 47.720854 | K14: 20.774313
A15: 202 | F15: AA0002 | H15: 070630Z MAY 26 | J15: 181.87783 | K15: 29.391679
A16: 203 | F16: AA0002 | H16: 070700Z MAY 26 | J16: 183.65483 | K16: 29.423931
A17: 204 | F17: AA0002 | H17: 070900Z MAY 26 | J17: 71.19669 | K17: 27.495426
A18: 205 | F18: AA0003 | H18: 070630Z MAY 26 | J18: 341.19356 | K18: 40.049982
A19: 206 | F19: AA0003 | H19: 070700Z MAY 26 | J19: 344.65993 | K19: 40.100155
A20: 207 | F20: AA0003 | H20: 070900Z MAY 26 | J20: 118.65228 | K20: 37.085375
A21: 208 | B21: Firing pos. Setermoen | C21: CM pos. Setermoen | D21: Low | E21: METCM (from METGM) | F21: AA0001 | G21: 140612Z APR 26 | H21: 080630Z MAY 26 | I21: 15990 | J21: 59.462838 | K21: 21.440183
A22: 209 | F22: AA0001 | H22: 080700Z MAY 26 | J22: 59.712295 | K22: 21.45126
A23: 210 | F23: AA0001 | H23: 080900Z MAY 26 | J23: 60.696904 | K23: 21.494702
A24: 211 | F24: AA0002 | H24: 080630Z MAY 26 | J24: 176.56433 | K24: 32.990616
A25: 212 | F25: AA0002 | H25: 080700Z MAY 26 | J25: 178.42511 | K25: 33.074221
A26: 213 | F26: AA0002 | H26: 080900Z MAY 26 | J26: 185.67856 | K26: 33.400517
A27: 214 | F27: AA0003 | H27: 080630Z MAY 26 | J27: 328.9427 | K27: 47.877719
A28: 215 | F28: AA0003 | H28: 080700Z MAY 26 | J28: 332.56811 | K28: 48.033827
A29: 216 | F29: AA0003 | H29: 080900Z MAY 26 | J29: 346.68783 | K29: 48.64202
A30: 217 | B30: Firing pos. Setermoen | C30: CM pos. Setermoen | D30: Low | E30: METCM (from METGM) | F30: AA0001 | G30: 090600Z APR 26 | H30: 090630Z MAY 26 | I30: 15990 | J30: 61.212195 | K30: 21.902297
A31: 218 | F31: AA0001 | H31: 090700Z MAY 26 | J31: 61.480945 | K31: 21.920163
A32: 219 | F32: AA0001 | H32: 090900Z MAY 26 | J32: 62.539624 | K32: 21.990183
A33: 220 | F33: AA0002 | H33: 090630Z MAY 26 | J33: 178.22007 | K33: 35.761263
A34: 221 | F34: AA0002 | H34: 090700Z MAY 26 | J34: 180.08881 | K34: 35.879229
A35: 222 | F35: AA0002 | H35: 090900Z MAY 26 | J35: 187.37248 | K35: 36.338781
A36: 223 | F36: AA0003 | H36: 090630Z MAY 26 | J36: 332.17697 | K36: 58.432231
A37: 224 | F37: AA0003 | H37: 090700Z MAY 26 | J37: 335.81639 | K37: 58.707275
A38: 225 | F38: AA0003 | H38: 090900Z MAY 26 | J38: 349.98945 | K38: 59.775139
A39: 226 | B39: Firing pos. Setermoen | C39: CM pos. Setermoen | D39: Low | E39: METCM (from METGM) | F39: AA0001 | G39: 160606Z APR 26 | H39: 100630Z MAY 26 | I39: 15990 | J39: 57.462385 | K39: 20.910845
A40: 227 | F40: AA0001 | H40: 100700Z MAY 26 | J40: 57.689337 | K40: 20.913966
...

Sheet METCM (from METGC)
A1: Test ID | B1: Firing pos. | C1: Weather pos. | D1: Angle of fire | E1: Weather format | F1: Target name | G1: Timestamps | I1: Measured alt. | J1: missdistance
G2: Weather DTG | H2: Fire DTG | J2: range | K2: cross
A3: 244 | B3: Firing pos. Setermoen | C3: CM pos. Setermoen | D3: Low | E3: METCM (from METGC) | F3: AA0001 | G3: 060600Z MAY 26 | H3: 060630Z MAY 26 | I3: 15990 | J3: 189.71471 | K3: 21.869515
A4: 245 | F4: AA0001 | H4: 060700Z MAY 26 | J4: 189.78069 | K4: 21.870076
A5: 246 | F5: AA0001 | H5: 060900Z MAY 26 | J5: 190.04437 | K5: 21.872318
A6: 247 | F6: AA0002 | H6: 060630Z MAY 26 | J6: 935.13331 | K6: 52.714034
A7: 248 | F7: AA0002 | H7: 060700Z MAY 26 | J7: 935.47911 | K7: 52.723667
A8: 249 | F8: AA0002 | H8: 060900Z MAY 26 | J8: 936.86099 | K8: 52.762157
A9: 250 | F9: AA0003 | H9: 060630Z MAY 26 | J9: 1789.3049 | K9: 80.357745
A10: 251 | F10: AA0003 | H10: 060700Z MAY 26 | J10: 1789.9684 | K10: 80.373589
A11: 252 | F11: AA0003 | H11: 060900Z MAY 26 | J11: 1792.6196 | K11: 80.436893
A12: 253 | B12: Firing pos. Setermoen | C12: CM pos. Setermoen | D12: Low | E12: METCM (from METGC) | F12: AA0001 | G12: 130924Z APR 26 | H12: 070630Z MAY 26 | I12: 15990 | J12: 57.894663 | K12: 21.022971
A13: 254 | F13: AA0001 | H13: 070700Z MAY 26 | J13: 58.126521 | K13: 21.027793
A14: 255 | F14: AA0001 | H14: 070900Z MAY 26 | J14: 59.043545 | K14: 21.04672
A15: 256 | F15: AA0002 | H15: 070630Z MAY 26 | J15: 174.5567 | K15: 29.259387
A16: 257 | F16: AA0002 | H16: 070700Z MAY 26 | J16: 176.40795 | K16: 29.292749
A17: 258 | F17: AA0002 | H17: 070900Z MAY 26 | J17: 183.62523 | K17: 29.423393
A18: 259 | F18: AA0003 | H18: 070630Z MAY 26 | J18: 326.8991 | K18: 39.844108
A19: 260 | F19: AA0003 | H19: 070700Z MAY 26 | J19: 330.51576 | K19: 39.896038
A20: 261 | F20: AA0003 | H20: 070900Z MAY 26 | J20: 344.6022 | K20: 40.099318
A21: 262 | B21: Firing pos. Setermoen | C21: CM pos. Setermoen | D21: Low | E21: METCM (from METGC) | F21: AA0001 | G21: 140612Z APR 26 | H21: 080630Z MAY 26 | I21: 15990 | J21: 59.462838 | K21: 21.440183
A22: 263 | F22: AA0001 | H22: 080700Z MAY 26 | J22: 59.712295 | K22: 21.45126
A23: 264 | F23: AA0001 | H23: 080900Z MAY 26 | J23: 60.696904 | K23: 21.494702
A24: 265 | F24: AA0002 | H24: 080630Z MAY 26 | J24: 176.56433 | K24: 32.990616
A25: 266 | F25: AA0002 | H25: 080700Z MAY 26 | J25: 178.42511 | K25: 33.074221
A26: 267 | F26: AA0002 | H26: 080900Z MAY 26 | J26: 185.67856 | K26: 33.400517
A27: 268 | F27: AA0003 | H27: 080630Z MAY 26 | J27: 328.9427 | K27: 47.877719
A28: 269 | F28: AA0003 | H28: 080700Z MAY 26 | J28: 332.56811 | K28: 48.033827
A29: 270 | F29: AA0003 | H29: 080900Z MAY 26 | J29: 346.68783 | K29: 48.64202
A30: 271 | B30: Firing pos. Setermoen | C30: CM pos. Setermoen | D30: Low | E30: METCM (from METGC) | F30: AA0001 | G30: 090600Z APR 26 | H30: 090630Z MAY 26 | I30: 15990 | J30: 61.212195 | K30: 21.902297
A31: 272 | F31: AA0001 | H31: 090700Z MAY 26 | J31: 61.480945 | K31: 21.920163
A32: 273 | F32: AA0001 | H32: 090900Z MAY 26 | J32: 62.539624 | K32: 21.990183
A33: 274 | F33: AA0002 | H33: 090630Z MAY 26 | J33: 178.22007 | K33: 35.761263
A34: 275 | F34: AA0002 | H34: 090700Z MAY 26 | J34: 180.08881 | K34: 35.879229
A35: 276 | F35: AA0002 | H35: 090900Z MAY 26 | J35: 187.37248 | K35: 36.338781
A36: 277 | F36: AA0003 | H36: 090630Z MAY 26 | J36: 332.17697 | K36: 58.432231
A37: 278 | F37: AA0003 | H37: 090700Z MAY 26 | J37: 335.81639 | K37: 58.707275
A38: 279 | F38: AA0003 | H38: 090900Z MAY 26 | J38: 349.98945 | K38: 59.775139
A39: 280 | B39: Firing pos. Setermoen | C39: CM pos. Setermoen | D39: Low | E39: METCM (from METGC) | F39: AA0001 | G39: 160606Z APR 26 | H39: 100630Z MAY 26 | I39: 15990 | J39: 57.462385 | K39: 20.910845
A40: 281 | F40: AA0001 | H40: 100700Z MAY 26 | J40: 57.689337 | K40: 20.913966
...

Sheet Statistikk
A1: Test ID | B1: Firing pos. | C1: Weather pos. | D1: Weather format | E1: Target name | F1: Fire DTG | G1: Measured alt. | H1: Type of stat. | I1: missdistance
I2: range | J2: cross
B3: Firing pos. Harstad | C3: CM pos. Harstad | D3: METCM | E3: AA0001 | F3: 231300Z FEB 26 | G3: 6000 | H3: n (antall) | I3: =COUNT('METCM (Meteomatics)'!J165:J169) -> 5 | J3: =COUNT('METCM (Meteomatics)'!K165:K169) -> 5
H4: Gjennomsnitt | I4: =AVERAGE('METCM (Meteomatics)'!J165:J169) -> 252.11618 | J4: =AVERAGE('METCM (Meteomatics)'!K165:K169) -> 35.163065
H5: Standardavvik (utvalg) | I5: =_xlfn.STDEV.S('METCM (Meteomatics)'!J165:J169) -> 7.562202 | J5: =_xlfn.STDEV.S('METCM (Meteomatics)'!K165:K169) -> 0.17132996
H6: Median | I6: =MEDIAN('METCM (Meteomatics)'!J165:J169) -> 250.92734 | J6: =MEDIAN('METCM (Meteomatics)'!K165:K169) -> 35.135865
H7: Q1 | I7: =_xlfn.QUARTILE.INC('METCM (Meteomatics)'!J165:J169,1) -> 246.60966 | J7: =_xlfn.QUARTILE.INC('METCM (Meteomatics)'!K165:K169,1) -> 35.038342
H8: Q3 | I8: =_xlfn.QUARTILE.INC('METCM (Meteomatics)'!J165:J169,3) -> 255.17105 | J8: =_xlfn.QUARTILE.INC('METCM (Meteomatics)'!K165:K169,3) -> 35.231962 | L8: Totale gjennomsnitt for Harstad
H9: IQR | I9: =I8-I7 -> 8.561391 | J9: =J8-J7 -> 0.19362 | L9: range | M9: cross
H10: 95% KI - nedre | I10: =I4-_xlfn.CONFIDENCE.T(0.05,I5,I3) -> 242.72646 | J10: =J4-_xlfn.CONFIDENCE.T(0.05,J5,J3) -> 34.950331 | L10: =AVERAGE(I4,I13,I22) -> 262.32281 | M10: =AVERAGE(J4,J13,J22) -> 36.459206
H11: 95% KI - øvre | I11: =I4+_xlfn.CONFIDENCE.T(0.05,I5,I3) -> 261.50589 | J11: =J4+_xlfn.CONFIDENCE.T(0.05,J5,J3) -> 35.375799
E12: AA0002 | H12: n (antall) | I12: =COUNT('METCM (Meteomatics)'!J170:J174) -> 5 | J12: =COUNT('METCM (Meteomatics)'!K170:K174) -> 5
H13: Gjennomsnitt | I13: =AVERAGE('METCM (Meteomatics)'!J170:J174) -> 257.30057 | J13: =AVERAGE('METCM (Meteomatics)'!K170:K174) -> 37.442109
H14: Standardavvik (utvalg) | I14: =_xlfn.STDEV.S('METCM (Meteomatics)'!J170:J174) -> 7.7323306 | J14: =_xlfn.STDEV.S('METCM (Meteomatics)'!K170:K174) -> 0.23121275
H15: Median | I15: =MEDIAN('METCM (Meteomatics)'!J170:J174) -> 256.08505 | J15: =MEDIAN('METCM (Meteomatics)'!K170:K174) -> 37.405506
H16: Q1 | I16: =_xlfn.QUARTILE.INC('METCM (Meteomatics)'!J170:J174,1) -> 251.67017 | J16: =_xlfn.QUARTILE.INC('METCM (Meteomatics)'!K170:K174,1) -> 37.273779
H17: Q3 | I17: =_xlfn.QUARTILE.INC('METCM (Meteomatics)'!J170:J174,3) -> 260.42424 | J17: =_xlfn.QUARTILE.INC('METCM (Meteomatics)'!K170:K174,3) -> 37.535212
H18: IQR | I18: =I17-I16 -> 8.754075 | J18: =J17-J16 -> 0.261433
H19: 95% KI - nedre | I19: =I13-_xlfn.CONFIDENCE.T(0.05,I14,I12) -> 247.69961 | J19: =J13-_xlfn.CONFIDENCE.T(0.05,J14,J12) -> 37.15502
H20: 95% KI - øvre | I20: =I13+_xlfn.CONFIDENCE.T(0.05,I14,I12) -> 266.90152 | J20: =J13+_xlfn.CONFIDENCE.T(0.05,J14,J12) -> 37.729197
E21: AA0003 | H21: n (antall) | I21: =COUNT('METCM (Meteomatics)'!J175:J179) -> 5 | J21: =COUNT('METCM (Meteomatics)'!K175:K179) -> 5
H22: Gjennomsnitt | I22: =AVERAGE('METCM (Meteomatics)'!J175:J179) -> 277.55169 | J22: =AVERAGE('METCM (Meteomatics)'!K175:K179) -> 36.772444
H23: Standardavvik (utvalg) | I23: =_xlfn.STDEV.S('METCM (Meteomatics)'!J175:J179) -> 8.3514757 | J23: =_xlfn.STDEV.S('METCM (Meteomatics)'!K175:K179) -> 0.18167332
H24: Median | I24: =MEDIAN('METCM (Meteomatics)'!J175:J179) -> 276.2387 | J24: =MEDIAN('METCM (Meteomatics)'!K175:K179) -> 36.743606
H25: Q1 | I25: =_xlfn.QUARTILE.INC('METCM (Meteomatics)'!J175:J179,1) -> 271.47046 | J25: =_xlfn.QUARTILE.INC('METCM (Meteomatics)'!K175:K179,1) -> 36.640191
H26: Q3 | I26: =_xlfn.QUARTILE.INC('METCM (Meteomatics)'!J175:J179,3) -> 280.92532 | J26: =_xlfn.QUARTILE.INC('METCM (Meteomatics)'!K175:K179,3) -> 36.845505
H27: IQR | I27: =I26-I25 -> 9.454852 | J27: =J26-J25 -> 0.205314
H28: 95% KI - nedre | I28: =I22-_xlfn.CONFIDENCE.T(0.05,I23,I21) -> 267.18196 | J28: =J22-_xlfn.CONFIDENCE.T(0.05,J23,J21) -> 36.546867
H29: 95% KI - øvre | I29: =I22+_xlfn.CONFIDENCE.T(0.05,I23,I21) -> 287.92141 | J29: =J22+_xlfn.CONFIDENCE.T(0.05,J23,J21) -> 36.998021
B30: Firing pos. Andøya | C30: CM pos. Andøya | D30: METCM | E30: AA0001 | F30: 09-23. APR 26 | G30: 5000 | H30: n (antall) | I30: =COUNT('METCM (Meteomatics)'!J129:J131,'METCM (Meteomatics)'!J138:J140,'METCM (Meteomatics)'!J147:J149,'METCM (Meteomatics)'!J156:J158) -> 12 | J30: =COUNT('METCM (Meteomatics)'!K129:K131,'METCM (Meteomatics)'!K138:K140,'METCM (Meteomatics)'!K147:K149,'METCM (Meteomatics)'!K156:K158) -> 12
H31: Gjennomsnitt | I31: =AVERAGE('METCM (Meteomatics)'!J129:J131,'METCM (Meteomatics)'!J138:J140,'METCM (Meteomatics)'!J147:J149,'METCM (Meteomatics)'!J156:J158) -> 65.825832 | J31: =AVERAGE('METCM (Meteomatics)'!K129:K131,'METCM (Meteomatics)'!K138:K140,'METCM (Meteomatics)'!K147:K149,'METCM (Meteomatics)'!K156:K158) -> 20.740059
H32: Standardavvik (utvalg) | I32: =_xlfn.STDEV.S('METCM (Meteomatics)'!J129:J131,'METCM (Meteomatics)'!J138:J140,'METCM (Meteomatics)'!J147:J149,'METCM (Meteomatics)'!J156:J158) -> 18.851273 | J32: =_xlfn.STDEV.S('METCM (Meteomatics)'!K129:K131,'METCM (Meteomatics)'!K138:K140,'METCM (Meteomatics)'!K147:K149,'METCM (Meteomatics)'!K156:K158) -> 0.12804012
H33: Median | I33: =MEDIAN('METCM (Meteomatics)'!J129:J131,'METCM (Meteomatics)'!J138:J140,'METCM (Meteomatics)'!J147:J149,'METCM (Meteomatics)'!J156:J158) -> 57.376914 | J33: =MEDIAN('METCM (Meteomatics)'!K129:K131,'METCM (Meteomatics)'!K138:K140,'METCM (Meteomatics)'!K147:K149,'METCM (Meteomatics)'!K156:K158) -> 20.68901
H34: Q1 | I34: =_xlfn.QUARTILE.INC(('METCM (Meteomatics)'!J129:J131,'METCM (Meteomatics)'!J138:J140,'METCM (Meteomatics)'!J147:J149,'METCM (Meteomatics)'!J156:J158),1) -> 53.459353 | J34: =_xlfn.QUARTILE.INC(('METCM (Meteomatics)'!K129:K131,'METCM (Meteomatics)'!K138:K140,'METCM (Meteomatics)'!K147:K149,'METCM (Meteomatics)'!K156:K158),1) -> 20.644764
H35: Q3 | I35: =_xlfn.QUARTILE.INC(('METCM (Meteomatics)'!J129:J131,'METCM (Meteomatics)'!J138:J140,'METCM (Meteomatics)'!J147:J149,'METCM (Meteomatics)'!J156:J158),3) -> 68.998953 | J35: =_xlfn.QUARTILE.INC(('METCM (Meteomatics)'!K129:K131,'METCM (Meteomatics)'!K138:K140,'METCM (Meteomatics)'!K147:K149,'METCM (Meteomatics)'!K156:K158),3) -> 20.777419
H36: IQR | I36: =I35-I34 -> 15.5396 | J36: =J35-J34 -> 0.1326555
H37: 95% KI - nedre | I37: =I31-_xlfn.CONFIDENCE.T(0.05,I32,I30) -> 53.848305 | J37: =J31-_xlfn.CONFIDENCE.T(0.05,J32,J30) -> 20.658707
G38: 3000 | H38: 95% KI - øvre | I38: =I31+_xlfn.CONFIDENCE.T(0.05,I32,I30) -> 77.80336 | J38: =J31+_xlfn.CONFIDENCE.T(0.05,J32,J30) -> 20.821412
E39: AA0002 | H39: n (antall) | I39: =COUNT('METCM (Meteomatics)'!J132:J134,'METCM (Meteomatics)'!J141:J143,'METCM (Meteomatics)'!J150:J152,'METCM (Meteomatics)'!J159:J161) -> 12 | J39: =COUNT('METCM (Meteomatics)'!K132:K134,'METCM (Meteomatics)'!K141:K143,'METCM (Meteomatics)'!K150:K152,'METCM (Meteomatics)'!K159:K161) -> 12
H40: Gjennomsnitt | I40: =AVERAGE('METCM (Meteomatics)'!J132:J134,'METCM (Meteomatics)'!J141:J143,'METCM (Meteomatics)'!J150:J152,'METCM (Meteomatics)'!J159:J161) -> 190.70864 | J40: =AVERAGE('METCM (Meteomatics)'!K132:K134,'METCM (Meteomatics)'!K141:K143,'METCM (Meteomatics)'!K150:K152,'METCM (Meteomatics)'!K159:K161) -> 28.143131
...

Sheet Statistikk-tidsbasert
A1: Test ID | B1: Firing pos. | C1: Weather pos. | D1: Weather format | E1: Target name | F1: Fire DTG | G1: Measured alt. | H1: Type of stat. | I1: missdistance 30 min | K1: missdistance 1 t | M1: missdistance 3 t
I2: range | J2: cross | K2: range | L2: cross | M2: range | N2: cross
B3: Firing pos. Harstad | C3: CM pos. Harstad | D3: METCM | E3: AA0001 | F3: 231300Z FEB 26 | G3: 6000 | H3: n (antall) | I3: =COUNT('METCM (Meteomatics)'!J165) -> 1 | J3: =COUNT('METCM (Meteomatics)'!K165) -> 1 | K3: =COUNT('METCM (Meteomatics)'!J166) -> 1 | L3: =COUNT('METCM (Meteomatics)'!K166) -> 1 | M3: =COUNT('METCM (Meteomatics)'!J168) -> 1 | N3: =COUNT('METCM (Meteomatics)'!K168) -> 1
H4: Gjennomsnitt | I4: =AVERAGE('METCM (Meteomatics)'!J165) -> 244.42185 | J4: =AVERAGE('METCM (Meteomatics)'!K165) -> 34.989025 | K4: =AVERAGE('METCM (Meteomatics)'!J166) -> 246.60966 | L4: =AVERAGE('METCM (Meteomatics)'!K166) -> 35.038342 | M4: =AVERAGE('METCM (Meteomatics)'!J168) -> 255.17105 | N4: =AVERAGE('METCM (Meteomatics)'!K168) -> 35.231962
H5: Standardavvik (utvalg) | I5: =_xlfn.STDEV.S('METCM (Meteomatics)'!J165) -> #DIV/0! | J5: =_xlfn.STDEV.S('METCM (Meteomatics)'!K165) -> #DIV/0! | K5: =_xlfn.STDEV.S('METCM (Meteomatics)'!J166) -> #DIV/0! | L5: =_xlfn.STDEV.S('METCM (Meteomatics)'!K166) -> #DIV/0! | M5: =_xlfn.STDEV.S('METCM (Meteomatics)'!J168) -> #DIV/0! | N5: =_xlfn.STDEV.S('METCM (Meteomatics)'!K168) -> #DIV/0!
H6: Median | I6: =MEDIAN('METCM (Meteomatics)'!J165) -> 244.42185 | J6: =MEDIAN('METCM (Meteomatics)'!K165) -> 34.989025 | K6: =MEDIAN('METCM (Meteomatics)'!J166) -> 246.60966 | L6: =MEDIAN('METCM (Meteomatics)'!K166) -> 35.038342 | M6: =MEDIAN('METCM (Meteomatics)'!J168) -> 255.17105 | N6: =MEDIAN('METCM (Meteomatics)'!K168) -> 35.231962
H7: Q1 | I7: =_xlfn.QUARTILE.INC(('METCM (Meteomatics)'!J165),1) -> 244.42185 | J7: =_xlfn.QUARTILE.INC(('METCM (Meteomatics)'!K165),1) -> 34.989025 | K7: =_xlfn.QUARTILE.INC(('METCM (Meteomatics)'!J166),1) -> 246.60966 | L7: =_xlfn.QUARTILE.INC(('METCM (Meteomatics)'!K166),1) -> 35.038342 | M7: =_xlfn.QUARTILE.INC(('METCM (Meteomatics)'!J168),1) -> 255.17105 | N7: =_xlfn.QUARTILE.INC(('METCM (Meteomatics)'!K168),1) -> 35.231962
H8: Q3 | I8: =_xlfn.QUARTILE.INC(('METCM (Meteomatics)'!J165),3) -> 244.42185 | J8: =_xlfn.QUARTILE.INC(('METCM (Meteomatics)'!K165),3) -> 34.989025 | K8: =_xlfn.QUARTILE.INC(('METCM (Meteomatics)'!J166),3) -> 246.60966 | L8: =_xlfn.QUARTILE.INC(('METCM (Meteomatics)'!K166),3) -> 35.038342 | M8: =_xlfn.QUARTILE.INC(('METCM (Meteomatics)'!J168),3) -> 255.17105 | N8: =_xlfn.QUARTILE.INC(('METCM (Meteomatics)'!K168),3) -> 35.231962
H9: IQR | I9: =I8-I7 -> 0 | J9: =J8-J7 -> 0 | K9: =K8-K7 -> 0 | L9: =L8-L7 -> 0 | M9: =M8-M7 -> 0 | N9: =N8-N7 -> 0
H10: 95% KI - nedre | I10: =I4-_xlfn.CONFIDENCE.T(0.05,I5,I3) -> #DIV/0! | J10: =J4-_xlfn.CONFIDENCE.T(0.05,J5,J3) -> #DIV/0! | K10: =K4-_xlfn.CONFIDENCE.T(0.05,K5,K3) -> #DIV/0! | L10: =L4-_xlfn.CONFIDENCE.T(0.05,L5,L3) -> #DIV/0! | M10: =M4-_xlfn.CONFIDENCE.T(0.05,M5,M3) -> #DIV/0! | N10: =N4-_xlfn.CONFIDENCE.T(0.05,N5,N3) -> #DIV/0!
H11: 95% KI - øvre | I11: =I4+_xlfn.CONFIDENCE.T(0.05,I5,I3) -> #DIV/0! | J11: =J4+_xlfn.CONFIDENCE.T(0.05,J5,J3) -> #DIV/0! | K11: =K4+_xlfn.CONFIDENCE.T(0.05,K5,K3) -> #DIV/0! | L11: =L4+_xlfn.CONFIDENCE.T(0.05,L5,L3) -> #DIV/0! | M11: =M4+_xlfn.CONFIDENCE.T(0.05,M5,M3) -> #DIV/0! | N11: =N4+_xlfn.CONFIDENCE.T(0.05,N5,N3) -> #DIV/0!
E12: AA0002 | H12: n (antall) | I12: =COUNT('METCM (Meteomatics)'!J170) -> 1 | J12: =COUNT('METCM (Meteomatics)'!K170) -> 1 | K12: =COUNT('METCM (Meteomatics)'!J171) -> 1 | L12: =COUNT('METCM (Meteomatics)'!K171) -> 1 | M12: =COUNT('METCM (Meteomatics)'!J173) -> 1 | N12: =COUNT('METCM (Meteomatics)'!K173) -> 1
H13: Gjennomsnitt | I13: =AVERAGE('METCM (Meteomatics)'!J170) -> 249.43308 | J13: =AVERAGE('METCM (Meteomatics)'!K170) -> 37.207127 | K13: =AVERAGE('METCM (Meteomatics)'!J171) -> 251.67017 | L13: =AVERAGE('METCM (Meteomatics)'!K171) -> 37.273779 | M13: =AVERAGE('METCM (Meteomatics)'!J173) -> 260.42424 | N13: =AVERAGE('METCM (Meteomatics)'!K173) -> 37.535212
H14: Standardavvik (utvalg) | I14: =_xlfn.STDEV.S('METCM (Meteomatics)'!J170) -> #DIV/0! | J14: =_xlfn.STDEV.S('METCM (Meteomatics)'!K170) -> #DIV/0! | K14: =_xlfn.STDEV.S('METCM (Meteomatics)'!J171) -> #DIV/0! | L14: =_xlfn.STDEV.S('METCM (Meteomatics)'!K171) -> #DIV/0! | M14: =_xlfn.STDEV.S('METCM (Meteomatics)'!J173) -> #DIV/0! | N14: =_xlfn.STDEV.S('METCM (Meteomatics)'!K173) -> #DIV/0!
H15: Median | I15: =MEDIAN('METCM (Meteomatics)'!J170) -> 249.43308 | J15: =MEDIAN('METCM (Meteomatics)'!K170) -> 37.207127 | K15: =MEDIAN('METCM (Meteomatics)'!J171) -> 251.67017 | L15: =MEDIAN('METCM (Meteomatics)'!K171) -> 37.273779 | M15: =MEDIAN('METCM (Meteomatics)'!J173) -> 260.42424 | N15: =MEDIAN('METCM (Meteomatics)'!K173) -> 37.535212
H16: Q1 | I16: =_xlfn.QUARTILE.INC(('METCM (Meteomatics)'!J170),1) -> 249.43308 | J16: =_xlfn.QUARTILE.INC(('METCM (Meteomatics)'!K170),1) -> 37.207127 | K16: =_xlfn.QUARTILE.INC(('METCM (Meteomatics)'!J171),1) -> 251.67017 | L16: =_xlfn.QUARTILE.INC(('METCM (Meteomatics)'!K171),1) -> 37.273779 | M16: =_xlfn.QUARTILE.INC(('METCM (Meteomatics)'!J173),1) -> 260.42424 | N16: =_xlfn.QUARTILE.INC(('METCM (Meteomatics)'!K173),1) -> 37.535212
H17: Q3 | I17: =_xlfn.QUARTILE.INC(('METCM (Meteomatics)'!J170),3) -> 249.43308 | J17: =_xlfn.QUARTILE.INC(('METCM (Meteomatics)'!K170),3) -> 37.207127 | K17: =_xlfn.QUARTILE.INC(('METCM (Meteomatics)'!J171),3) -> 251.67017 | L17: =_xlfn.QUARTILE.INC(('METCM (Meteomatics)'!K171),3) -> 37.273779 | M17: =_xlfn.QUARTILE.INC(('METCM (Meteomatics)'!J173),3) -> 260.42424 | N17: =_xlfn.QUARTILE.INC(('METCM (Meteomatics)'!K173),3) -> 37.535212
H18: IQR | I18: =I17-I16 -> 0 | J18: =J17-J16 -> 0 | K18: =K17-K16 -> 0 | L18: =L17-L16 -> 0 | M18: =M17-M16 -> 0 | N18: =N17-N16 -> 0
H19: 95% KI - nedre | I19: =I13-_xlfn.CONFIDENCE.T(0.05,I14,I12) -> #DIV/0! | J19: =J13-_xlfn.CONFIDENCE.T(0.05,J14,J12) -> #DIV/0! | K19: =K13-_xlfn.CONFIDENCE.T(0.05,K14,K12) -> #DIV/0! | L19: =L13-_xlfn.CONFIDENCE.T(0.05,L14,L12) -> #DIV/0! | M19: =M13-_xlfn.CONFIDENCE.T(0.05,M14,M12) -> #DIV/0! | N19: =N13-_xlfn.CONFIDENCE.T(0.05,N14,N12) -> #DIV/0!
H20: 95% KI - øvre | I20: =I13+_xlfn.CONFIDENCE.T(0.05,I14,I12) -> #DIV/0! | J20: =J13+_xlfn.CONFIDENCE.T(0.05,J14,J12) -> #DIV/0! | K20: =K13+_xlfn.CONFIDENCE.T(0.05,K14,K12) -> #DIV/0! | L20: =L13+_xlfn.CONFIDENCE.T(0.05,L14,L12) -> #DIV/0! | M20: =M13+_xlfn.CONFIDENCE.T(0.05,M14,M12) -> #DIV/0! | N20: =N13+_xlfn.CONFIDENCE.T(0.05,N14,N12) -> #DIV/0!
E21: AA0003 | H21: n (antall) | I21: =COUNT('METCM (Meteomatics)'!J175) -> 1 | J21: =COUNT('METCM (Meteomatics)'!K175) -> 1 | K21: =COUNT('METCM (Meteomatics)'!J171) -> 1 | L21: =COUNT('METCM (Meteomatics)'!K171) -> 1 | M21: =COUNT('METCM (Meteomatics)'!J178) -> 1 | N21: =COUNT('METCM (Meteomatics)'!K178) -> 1
H22: Gjennomsnitt | I22: =AVERAGE('METCM (Meteomatics)'!J175) -> 269.05438 | J22: =AVERAGE('METCM (Meteomatics)'!K175) -> 36.587892 | K22: =AVERAGE('METCM (Meteomatics)'!J171) -> 251.67017 | L22: =AVERAGE('METCM (Meteomatics)'!K171) -> 37.273779 | M22: =AVERAGE('METCM (Meteomatics)'!J178) -> 280.92532 | N22: =AVERAGE('METCM (Meteomatics)'!K178) -> 36.845505
H23: Standardavvik (utvalg) | I23: =_xlfn.STDEV.S('METCM (Meteomatics)'!J175) -> #DIV/0! | J23: =_xlfn.STDEV.S('METCM (Meteomatics)'!K175) -> #DIV/0! | K23: =_xlfn.STDEV.S('METCM (Meteomatics)'!J171) -> #DIV/0! | L23: =_xlfn.STDEV.S('METCM (Meteomatics)'!K171) -> #DIV/0! | M23: =_xlfn.STDEV.S('METCM (Meteomatics)'!J178) -> #DIV/0! | N23: =_xlfn.STDEV.S('METCM (Meteomatics)'!K178) -> #DIV/0!
H24: Median | I24: =MEDIAN('METCM (Meteomatics)'!J175) -> 269.05438 | J24: =MEDIAN('METCM (Meteomatics)'!K175) -> 36.587892 | K24: =MEDIAN('METCM (Meteomatics)'!J171) -> 251.67017 | L24: =MEDIAN('METCM (Meteomatics)'!K171) -> 37.273779 | M24: =MEDIAN('METCM (Meteomatics)'!J178) -> 280.92532 | N24: =MEDIAN('METCM (Meteomatics)'!K178) -> 36.845505
H25: Q1 | I25: =_xlfn.QUARTILE.INC(('METCM (Meteomatics)'!J175),1) -> 269.05438 | J25: =_xlfn.QUARTILE.INC(('METCM (Meteomatics)'!K175),1) -> 36.587892 | K25: =_xlfn.QUARTILE.INC(('METCM (Meteomatics)'!J171),1) -> 251.67017 | L25: =_xlfn.QUARTILE.INC(('METCM (Meteomatics)'!K171),1) -> 37.273779 | M25: =_xlfn.QUARTILE.INC(('METCM (Meteomatics)'!J178),1) -> 280.92532 | N25: =_xlfn.QUARTILE.INC(('METCM (Meteomatics)'!K178),1) -> 36.845505
H26: Q3 | I26: =_xlfn.QUARTILE.INC(('METCM (Meteomatics)'!J175),3) -> 269.05438 | J26: =_xlfn.QUARTILE.INC(('METCM (Meteomatics)'!K175),3) -> 36.587892 | K26: =_xlfn.QUARTILE.INC(('METCM (Meteomatics)'!J171),3) -> 251.67017 | L26: =_xlfn.QUARTILE.INC(('METCM (Meteomatics)'!K171),3) -> 37.273779 | M26: =_xlfn.QUARTILE.INC(('METCM (Meteomatics)'!J178),3) -> 280.92532 | N26: =_xlfn.QUARTILE.INC(('METCM (Meteomatics)'!K178),3) -> 36.845505
H27: IQR | I27: =I26-I25 -> 0 | J27: =J26-J25 -> 0 | K27: =K26-K25 -> 0 | L27: =L26-L25 -> 0 | M27: =M26-M25 -> 0 | N27: =N26-N25 -> 0
H28: 95% KI - nedre | I28: =I22-_xlfn.CONFIDENCE.T(0.05,I23,I21) -> #DIV/0! | J28: =J22-_xlfn.CONFIDENCE.T(0.05,J23,J21) -> #DIV/0! | K28: =K22-_xlfn.CONFIDENCE.T(0.05,K23,K21) -> #DIV/0! | L28: =L22-_xlfn.CONFIDENCE.T(0.05,L23,L21) -> #DIV/0! | M28: =M22-_xlfn.CONFIDENCE.T(0.05,M23,M21) -> #DIV/0! | N28: =N22-_xlfn.CONFIDENCE.T(0.05,N23,N21) -> #DIV/0!
H29: 95% KI - øvre | I29: =I22+_xlfn.CONFIDENCE.T(0.05,I23,I21) -> #DIV/0! | J29: =J22+_xlfn.CONFIDENCE.T(0.05,J23,J21) -> #DIV/0! | K29: =K22+_xlfn.CONFIDENCE.T(0.05,K23,K21) -> #DIV/0! | L29: =L22+_xlfn.CONFIDENCE.T(0.05,L23,L21) -> #DIV/0! | M29: =M22+_xlfn.CONFIDENCE.T(0.05,M23,M21) -> #DIV/0! | N29: =N22+_xlfn.CONFIDENCE.T(0.05,N23,N21) -> #DIV/0!
B30: Firing pos. Andøya | C30: CM pos. Andøya | D30: METCM | E30: AA0001 | F30: 09-23. APR 26 | G30: 5000 | H30: n (antall) | I30: =COUNT('METCM (Meteomatics)'!J129,'METCM (Meteomatics)'!J138,'METCM (Meteomatics)'!J147,'METCM (Meteomatics)'!J156) -> 4 | J30: =COUNT('METCM (Meteomatics)'!K129,'METCM (Meteomatics)'!K138,'METCM (Meteomatics)'!K147,'METCM (Meteomatics)'!K156) -> 4 | K30: =COUNT('METCM (Meteomatics)'!J130,'METCM (Meteomatics)'!J139,'METCM (Meteomatics)'!J148,'METCM (Meteomatics)'!J157) -> 4 | L30: =COUNT('METCM (Meteomatics)'!K130,'METCM (Meteomatics)'!K139,'METCM (Meteomatics)'!K148,'METCM (Meteomatics)'!K157) -> 4 | M30: =COUNT('METCM (Meteomatics)'!J131,'METCM (Meteomatics)'!J140,'METCM (Meteomatics)'!J149,'METCM (Meteomatics)'!J158) -> 4 | N30: =COUNT('METCM (Meteomatics)'!K131,'METCM (Meteomatics)'!K140,'METCM (Meteomatics)'!K149,'METCM (Meteomatics)'!K158) -> 4
H31: Gjennomsnitt | I31: =AVERAGE('METCM (Meteomatics)'!J129,'METCM (Meteomatics)'!J138,'METCM (Meteomatics)'!J147,'METCM (Meteomatics)'!J156) -> 64.062204 | J31: =AVERAGE('METCM (Meteomatics)'!K129,'METCM (Meteomatics)'!K138,'METCM (Meteomatics)'!K147,'METCM (Meteomatics)'!K156) -> 20.733349 | K31: =AVERAGE('METCM (Meteomatics)'!J130,'METCM (Meteomatics)'!J139,'METCM (Meteomatics)'!J148,'METCM (Meteomatics)'!J157) -> 65.105205 | L31: =AVERAGE('METCM (Meteomatics)'!K130,'METCM (Meteomatics)'!K139,'METCM (Meteomatics)'!K148,'METCM (Meteomatics)'!K157) -> 20.737189 | M31: =AVERAGE('METCM (Meteomatics)'!J131,'METCM (Meteomatics)'!J140,'METCM (Meteomatics)'!J149,'METCM (Meteomatics)'!J158) -> 68.310087 | N31: =AVERAGE('METCM (Meteomatics)'!K131,'METCM (Meteomatics)'!K140,'METCM (Meteomatics)'!K149,'METCM (Meteomatics)'!K158) -> 20.74964
H32: Standardavvik (utvalg) | I32: =_xlfn.STDEV.S('METCM (Meteomatics)'!J129,'METCM (Meteomatics)'!J138,'METCM (Meteomatics)'!J147,'METCM (Meteomatics)'!J156) -> 21.755507 | J32: =_xlfn.STDEV.S('METCM (Meteomatics)'!K129,'METCM (Meteomatics)'!K138,'METCM (Meteomatics)'!K147,'METCM (Meteomatics)'!K156) -> 0.14524618 | K32: =_xlfn.STDEV.S('METCM (Meteomatics)'!J130,'METCM (Meteomatics)'!J139,'METCM (Meteomatics)'!J148,'METCM (Meteomatics)'!J157) -> 21.084428 | L32: =_xlfn.STDEV.S('METCM (Meteomatics)'!K130,'METCM (Meteomatics)'!K139,'METCM (Meteomatics)'!K148,'METCM (Meteomatics)'!K157) -> 0.14281812 | M32: =_xlfn.STDEV.S('METCM (Meteomatics)'!J131,'METCM (Meteomatics)'!J140,'METCM (Meteomatics)'!J149,'METCM (Meteomatics)'!J158) -> 19.289937 | N32: =_xlfn.STDEV.S('METCM (Meteomatics)'!K131,'METCM (Meteomatics)'!K140,'METCM (Meteomatics)'!K149,'METCM (Meteomatics)'!K158) -> 0.13574038
H33: Median | I33: =MEDIAN('METCM (Meteomatics)'!J129,'METCM (Meteomatics)'!J138,'METCM (Meteomatics)'!J147,'METCM (Meteomatics)'!J156) -> 54.298051 | J33: =MEDIAN('METCM (Meteomatics)'!K129,'METCM (Meteomatics)'!K138,'METCM (Meteomatics)'!K147,'METCM (Meteomatics)'!K156) -> 20.676596 | K33: =MEDIAN('METCM (Meteomatics)'!J130,'METCM (Meteomatics)'!J139,'METCM (Meteomatics)'!J148,'METCM (Meteomatics)'!J157) -> 55.187722 | L33: =MEDIAN('METCM (Meteomatics)'!K130,'METCM (Meteomatics)'!K139,'METCM (Meteomatics)'!K148,'METCM (Meteomatics)'!K157) -> 20.680176 | M33: =MEDIAN('METCM (Meteomatics)'!J131,'METCM (Meteomatics)'!J140,'METCM (Meteomatics)'!J149,'METCM (Meteomatics)'!J158) -> 59.084114 | N33: =MEDIAN('METCM (Meteomatics)'!K131,'METCM (Meteomatics)'!K140,'METCM (Meteomatics)'!K149,'METCM (Meteomatics)'!K158) -> 20.693234
H34: Q1 | I34: =_xlfn.QUARTILE.INC(('METCM (Meteomatics)'!J129,'METCM (Meteomatics)'!J138,'METCM (Meteomatics)'!J147,'METCM (Meteomatics)'!J156),1) -> 51.744757 | J34: =_xlfn.QUARTILE.INC(('METCM (Meteomatics)'!K129,'METCM (Meteomatics)'!K138,'METCM (Meteomatics)'!K147,'METCM (Meteomatics)'!K156),1) -> 20.638861 | K34: =_xlfn.QUARTILE.INC(('METCM (Meteomatics)'!J130,'METCM (Meteomatics)'!J139,'METCM (Meteomatics)'!J148,'METCM (Meteomatics)'!J157),1) -> 53.459353 | L34: =_xlfn.QUARTILE.INC(('METCM (Meteomatics)'!K130,'METCM (Meteomatics)'!K139,'METCM (Meteomatics)'!K148,'METCM (Meteomatics)'!K157),1) -> 20.644764 | M34: =_xlfn.QUARTILE.INC(('METCM (Meteomatics)'!J131,'METCM (Meteomatics)'!J140,'METCM (Meteomatics)'!J149,'METCM (Meteomatics)'!J158),1) -> 58.213812 | N34: =_xlfn.QUARTILE.INC(('METCM (Meteomatics)'!K131,'METCM (Meteomatics)'!K140,'METCM (Meteomatics)'!K149,'METCM (Meteomatics)'!K158),1) -> 20.664321
H35: Q3 | I35: =_xlfn.QUARTILE.INC(('METCM (Meteomatics)'!J129,'METCM (Meteomatics)'!J138,'METCM (Meteomatics)'!J147,'METCM (Meteomatics)'!J156),3) -> 66.615499 | J35: =_xlfn.QUARTILE.INC(('METCM (Meteomatics)'!K129,'METCM (Meteomatics)'!K138,'METCM (Meteomatics)'!K147,'METCM (Meteomatics)'!K156),3) -> 20.771083 | K35: =_xlfn.QUARTILE.INC(('METCM (Meteomatics)'!J130,'METCM (Meteomatics)'!J139,'METCM (Meteomatics)'!J148,'METCM (Meteomatics)'!J157),3) -> 66.833575 | L35: =_xlfn.QUARTILE.INC(('METCM (Meteomatics)'!K130,'METCM (Meteomatics)'!K139,'METCM (Meteomatics)'!K148,'METCM (Meteomatics)'!K157),3) -> 20.772601 | M35: =_xlfn.QUARTILE.INC(('METCM (Meteomatics)'!J131,'METCM (Meteomatics)'!J140,'METCM (Meteomatics)'!J149,'METCM (Meteomatics)'!J158),3) -> 69.180389 | N35: =_xlfn.QUARTILE.INC(('METCM (Meteomatics)'!K131,'METCM (Meteomatics)'!K140,'METCM (Meteomatics)'!K149,'METCM (Meteomatics)'!K158),3) -> 20.778553
H36: IQR | I36: =I35-I34 -> 14.870742 | J36: =J35-J34 -> 0.13222175 | K36: =K35-K34 -> 13.374222 | L36: =L35-L34 -> 0.127837 | M36: =M35-M34 -> 10.966577 | N36: =N35-N34 -> 0.11423175
H37: 95% KI - nedre | I37: =I31-_xlfn.CONFIDENCE.T(0.05,I32,I30) -> 29.444337 | J37: =J31-_xlfn.CONFIDENCE.T(0.05,J32,J30) -> 20.50223 | K37: =K31-_xlfn.CONFIDENCE.T(0.05,K32,K30) -> 31.555175 | L37: =L31-_xlfn.CONFIDENCE.T(0.05,L32,L30) -> 20.509934 | M37: =M31-_xlfn.CONFIDENCE.T(0.05,M32,M30) -> 37.615492 | N37: =N31-_xlfn.CONFIDENCE.T(0.05,N32,N30) -> 20.533647
G38: 3000 | H38: 95% KI - øvre | I38: =I31+_xlfn.CONFIDENCE.T(0.05,I32,I30) -> 98.680071 | J38: =J31+_xlfn.CONFIDENCE.T(0.05,J32,J30) -> 20.964468 | K38: =K31+_xlfn.CONFIDENCE.T(0.05,K32,K30) -> 98.655235 | L38: =L31+_xlfn.CONFIDENCE.T(0.05,L32,L30) -> 20.964444 | M38: =M31+_xlfn.CONFIDENCE.T(0.05,M32,M30) -> 99.004682 | N38: =N31+_xlfn.CONFIDENCE.T(0.05,N32,N30) -> 20.965633
E39: AA0002 | H39: n (antall) | I39: =COUNT('METCM (Meteomatics)'!J132,'METCM (Meteomatics)'!J141,'METCM (Meteomatics)'!J150,'METCM (Meteomatics)'!J159) -> 4 | J39: =COUNT('METCM (Meteomatics)'!K132,'METCM (Meteomatics)'!K141,'METCM (Meteomatics)'!K150,'METCM (Meteomatics)'!K159) -> 4 | K39: =COUNT('METCM (Meteomatics)'!J133,'METCM (Meteomatics)'!J142,'METCM (Meteomatics)'!J151,'METCM (Meteomatics)'!J160) -> 4 | L39: =COUNT('METCM (Meteomatics)'!K133,'METCM (Meteomatics)'!K142,'METCM (Meteomatics)'!K151,'METCM (Meteomatics)'!K160) -> 4 | M39: =COUNT('METCM (Meteomatics)'!J134,'METCM (Meteomatics)'!J143,'METCM (Meteomatics)'!J152,'METCM (Meteomatics)'!J161) -> 4 | N39: =COUNT('METCM (Meteomatics)'!K134,'METCM (Meteomatics)'!K143,'METCM (Meteomatics)'!K152,'METCM (Meteomatics)'!K161) -> 4
H40: Gjennomsnitt | I40: =AVERAGE('METCM (Meteomatics)'!J132,'METCM (Meteomatics)'!J141,'METCM (Meteomatics)'!J150,'METCM (Meteomatics)'!J159) -> 182.55671 | J40: =AVERAGE('METCM (Meteomatics)'!K132,'METCM (Meteomatics)'!K141,'METCM (Meteomatics)'!K150,'METCM (Meteomatics)'!K159) -> 28.084126 | K40: =AVERAGE('METCM (Meteomatics)'!J133,'METCM (Meteomatics)'!J142,'METCM (Meteomatics)'!J151,'METCM (Meteomatics)'!J160) -> 187.33712 | L40: =AVERAGE('METCM (Meteomatics)'!K133,'METCM (Meteomatics)'!K142,'METCM (Meteomatics)'!K151,'METCM (Meteomatics)'!K160) -> 28.118152 | M40: =AVERAGE('METCM (Meteomatics)'!J134,'METCM (Meteomatics)'!J143,'METCM (Meteomatics)'!J152,'METCM (Meteomatics)'!J161) -> 202.2321 | N40: =AVERAGE('METCM (Meteomatics)'!K134,'METCM (Meteomatics)'!K143,'METCM (Meteomatics)'!K152,'METCM (Meteomatics)'!K161) -> 28.227116
...

Sheet Statistikk-tidsbasert (2)
A1: Test ID | B1: Firing pos. | C1: Weather pos. | D1: Weather format | E1: Target name | F1: Fire DTG | G1: Measured alt. | H1: Type of stat. | I1: missdistance 30 min | K1: missdistance 1 t | M1: missdistance 3 t
I2: range | J2: cross | K2: range | L2: cross | M2: range | N2: cross
B3: Firing pos. Harstad | C3: CM pos. Harstad | D3: METCM | E3: AA0001 | F3: 231300Z FEB 26 | G3: 6000 | H3: n (antall) | I3: =COUNT('METCM (Meteomatics)'!J165) -> 1 | J3: =COUNT('METCM (Meteomatics)'!K165) -> 1 | K3: =COUNT('METCM (Meteomatics)'!J166) -> 1 | L3: =COUNT('METCM (Meteomatics)'!K166) -> 1 | M3: =COUNT('METCM (Meteomatics)'!J168) -> 1 | N3: =COUNT('METCM (Meteomatics)'!K168) -> 1
H4: Gjennomsnitt | I4: =AVERAGE('METCM (Meteomatics)'!J165) -> 244.42185 | J4: =AVERAGE('METCM (Meteomatics)'!K165) -> 34.989025 | K4: =AVERAGE('METCM (Meteomatics)'!J166) -> 246.60966 | L4: =AVERAGE('METCM (Meteomatics)'!K166) -> 35.038342 | M4: =AVERAGE('METCM (Meteomatics)'!J168) -> 255.17105 | N4: =AVERAGE('METCM (Meteomatics)'!K168) -> 35.231962
H5: Standardavvik (utvalg) | I5: =_xlfn.STDEV.S('METCM (Meteomatics)'!J165) -> #DIV/0! | J5: =_xlfn.STDEV.S('METCM (Meteomatics)'!K165) -> #DIV/0! | K5: =_xlfn.STDEV.S('METCM (Meteomatics)'!J166) -> #DIV/0! | L5: =_xlfn.STDEV.S('METCM (Meteomatics)'!K166) -> #DIV/0! | M5: =_xlfn.STDEV.S('METCM (Meteomatics)'!J168) -> #DIV/0! | N5: =_xlfn.STDEV.S('METCM (Meteomatics)'!K168) -> #DIV/0!
H6: Median | I6: =MEDIAN('METCM (Meteomatics)'!J165) -> 244.42185 | J6: =MEDIAN('METCM (Meteomatics)'!K165) -> 34.989025 | K6: =MEDIAN('METCM (Meteomatics)'!J166) -> 246.60966 | L6: =MEDIAN('METCM (Meteomatics)'!K166) -> 35.038342 | M6: =MEDIAN('METCM (Meteomatics)'!J168) -> 255.17105 | N6: =MEDIAN('METCM (Meteomatics)'!K168) -> 35.231962
H7: Q1 | I7: =_xlfn.QUARTILE.INC(('METCM (Meteomatics)'!J165),1) -> 244.42185 | J7: =_xlfn.QUARTILE.INC(('METCM (Meteomatics)'!K165),1) -> 34.989025 | K7: =_xlfn.QUARTILE.INC(('METCM (Meteomatics)'!J166),1) -> 246.60966 | L7: =_xlfn.QUARTILE.INC(('METCM (Meteomatics)'!K166),1) -> 35.038342 | M7: =_xlfn.QUARTILE.INC(('METCM (Meteomatics)'!J168),1) -> 255.17105 | N7: =_xlfn.QUARTILE.INC(('METCM (Meteomatics)'!K168),1) -> 35.231962
H8: Q3 | I8: =_xlfn.QUARTILE.INC(('METCM (Meteomatics)'!J165),3) -> 244.42185 | J8: =_xlfn.QUARTILE.INC(('METCM (Meteomatics)'!K165),3) -> 34.989025 | K8: =_xlfn.QUARTILE.INC(('METCM (Meteomatics)'!J166),3) -> 246.60966 | L8: =_xlfn.QUARTILE.INC(('METCM (Meteomatics)'!K166),3) -> 35.038342 | M8: =_xlfn.QUARTILE.INC(('METCM (Meteomatics)'!J168),3) -> 255.17105 | N8: =_xlfn.QUARTILE.INC(('METCM (Meteomatics)'!K168),3) -> 35.231962
H9: IQR | I9: =I8-I7 -> 0 | J9: =J8-J7 -> 0 | K9: =K8-K7 -> 0 | L9: =L8-L7 -> 0 | M9: =M8-M7 -> 0 | N9: =N8-N7 -> 0
H10: 95% KI - nedre | I10: =I4-_xlfn.CONFIDENCE.T(0.05,I5,I3) -> #DIV/0! | J10: =J4-_xlfn.CONFIDENCE.T(0.05,J5,J3) -> #DIV/0! | K10: =K4-_xlfn.CONFIDENCE.T(0.05,K5,K3) -> #DIV/0! | L10: =L4-_xlfn.CONFIDENCE.T(0.05,L5,L3) -> #DIV/0! | M10: =M4-_xlfn.CONFIDENCE.T(0.05,M5,M3) -> #DIV/0! | N10: =N4-_xlfn.CONFIDENCE.T(0.05,N5,N3) -> #DIV/0!
H11: 95% KI - øvre | I11: =I4+_xlfn.CONFIDENCE.T(0.05,I5,I3) -> #DIV/0! | J11: =J4+_xlfn.CONFIDENCE.T(0.05,J5,J3) -> #DIV/0! | K11: =K4+_xlfn.CONFIDENCE.T(0.05,K5,K3) -> #DIV/0! | L11: =L4+_xlfn.CONFIDENCE.T(0.05,L5,L3) -> #DIV/0! | M11: =M4+_xlfn.CONFIDENCE.T(0.05,M5,M3) -> #DIV/0! | N11: =N4+_xlfn.CONFIDENCE.T(0.05,N5,N3) -> #DIV/0!
E12: AA0002 | H12: n (antall) | I12: =COUNT('METCM (Meteomatics)'!J170) -> 1 | J12: =COUNT('METCM (Meteomatics)'!K170) -> 1 | K12: =COUNT('METCM (Meteomatics)'!J171) -> 1 | L12: =COUNT('METCM (Meteomatics)'!K171) -> 1 | M12: =COUNT('METCM (Meteomatics)'!J173) -> 1 | N12: =COUNT('METCM (Meteomatics)'!K173) -> 1
H13: Gjennomsnitt | I13: =AVERAGE('METCM (Meteomatics)'!J170) -> 249.43308 | J13: =AVERAGE('METCM (Meteomatics)'!K170) -> 37.207127 | K13: =AVERAGE('METCM (Meteomatics)'!J171) -> 251.67017 | L13: =AVERAGE('METCM (Meteomatics)'!K171) -> 37.273779 | M13: =AVERAGE('METCM (Meteomatics)'!J173) -> 260.42424 | N13: =AVERAGE('METCM (Meteomatics)'!K173) -> 37.535212
H14: Standardavvik (utvalg) | I14: =_xlfn.STDEV.S('METCM (Meteomatics)'!J170) -> #DIV/0! | J14: =_xlfn.STDEV.S('METCM (Meteomatics)'!K170) -> #DIV/0! | K14: =_xlfn.STDEV.S('METCM (Meteomatics)'!J171) -> #DIV/0! | L14: =_xlfn.STDEV.S('METCM (Meteomatics)'!K171) -> #DIV/0! | M14: =_xlfn.STDEV.S('METCM (Meteomatics)'!J173) -> #DIV/0! | N14: =_xlfn.STDEV.S('METCM (Meteomatics)'!K173) -> #DIV/0!
H15: Median | I15: =MEDIAN('METCM (Meteomatics)'!J170) -> 249.43308 | J15: =MEDIAN('METCM (Meteomatics)'!K170) -> 37.207127 | K15: =MEDIAN('METCM (Meteomatics)'!J171) -> 251.67017 | L15: =MEDIAN('METCM (Meteomatics)'!K171) -> 37.273779 | M15: =MEDIAN('METCM (Meteomatics)'!J173) -> 260.42424 | N15: =MEDIAN('METCM (Meteomatics)'!K173) -> 37.535212
H16: Q1 | I16: =_xlfn.QUARTILE.INC(('METCM (Meteomatics)'!J170),1) -> 249.43308 | J16: =_xlfn.QUARTILE.INC(('METCM (Meteomatics)'!K170),1) -> 37.207127 | K16: =_xlfn.QUARTILE.INC(('METCM (Meteomatics)'!J171),1) -> 251.67017 | L16: =_xlfn.QUARTILE.INC(('METCM (Meteomatics)'!K171),1) -> 37.273779 | M16: =_xlfn.QUARTILE.INC(('METCM (Meteomatics)'!J173),1) -> 260.42424 | N16: =_xlfn.QUARTILE.INC(('METCM (Meteomatics)'!K173),1) -> 37.535212
H17: Q3 | I17: =_xlfn.QUARTILE.INC(('METCM (Meteomatics)'!J170),3) -> 249.43308 | J17: =_xlfn.QUARTILE.INC(('METCM (Meteomatics)'!K170),3) -> 37.207127 | K17: =_xlfn.QUARTILE.INC(('METCM (Meteomatics)'!J171),3) -> 251.67017 | L17: =_xlfn.QUARTILE.INC(('METCM (Meteomatics)'!K171),3) -> 37.273779 | M17: =_xlfn.QUARTILE.INC(('METCM (Meteomatics)'!J173),3) -> 260.42424 | N17: =_xlfn.QUARTILE.INC(('METCM (Meteomatics)'!K173),3) -> 37.535212
H18: IQR | I18: =I17-I16 -> 0 | J18: =J17-J16 -> 0 | K18: =K17-K16 -> 0 | L18: =L17-L16 -> 0 | M18: =M17-M16 -> 0 | N18: =N17-N16 -> 0
H19: 95% KI - nedre | I19: =I13-_xlfn.CONFIDENCE.T(0.05,I14,I12) -> #DIV/0! | J19: =J13-_xlfn.CONFIDENCE.T(0.05,J14,J12) -> #DIV/0! | K19: =K13-_xlfn.CONFIDENCE.T(0.05,K14,K12) -> #DIV/0! | L19: =L13-_xlfn.CONFIDENCE.T(0.05,L14,L12) -> #DIV/0! | M19: =M13-_xlfn.CONFIDENCE.T(0.05,M14,M12) -> #DIV/0! | N19: =N13-_xlfn.CONFIDENCE.T(0.05,N14,N12) -> #DIV/0!
H20: 95% KI - øvre | I20: =I13+_xlfn.CONFIDENCE.T(0.05,I14,I12) -> #DIV/0! | J20: =J13+_xlfn.CONFIDENCE.T(0.05,J14,J12) -> #DIV/0! | K20: =K13+_xlfn.CONFIDENCE.T(0.05,K14,K12) -> #DIV/0! | L20: =L13+_xlfn.CONFIDENCE.T(0.05,L14,L12) -> #DIV/0! | M20: =M13+_xlfn.CONFIDENCE.T(0.05,M14,M12) -> #DIV/0! | N20: =N13+_xlfn.CONFIDENCE.T(0.05,N14,N12) -> #DIV/0!
E21: AA0003 | H21: n (antall) | I21: =COUNT('METCM (Meteomatics)'!J175) -> 1 | J21: =COUNT('METCM (Meteomatics)'!K175) -> 1 | K21: =COUNT('METCM (Meteomatics)'!J171) -> 1 | L21: =COUNT('METCM (Meteomatics)'!K171) -> 1 | M21: =COUNT('METCM (Meteomatics)'!J178) -> 1 | N21: =COUNT('METCM (Meteomatics)'!K178) -> 1
H22: Gjennomsnitt | I22: =AVERAGE('METCM (Meteomatics)'!J175) -> 269.05438 | J22: =AVERAGE('METCM (Meteomatics)'!K175) -> 36.587892 | K22: =AVERAGE('METCM (Meteomatics)'!J171) -> 251.67017 | L22: =AVERAGE('METCM (Meteomatics)'!K171) -> 37.273779 | M22: =AVERAGE('METCM (Meteomatics)'!J178) -> 280.92532 | N22: =AVERAGE('METCM (Meteomatics)'!K178) -> 36.845505
H23: Standardavvik (utvalg) | I23: =_xlfn.STDEV.S('METCM (Meteomatics)'!J175) -> #DIV/0! | J23: =_xlfn.STDEV.S('METCM (Meteomatics)'!K175) -> #DIV/0! | K23: =_xlfn.STDEV.S('METCM (Meteomatics)'!J171) -> #DIV/0! | L23: =_xlfn.STDEV.S('METCM (Meteomatics)'!K171) -> #DIV/0! | M23: =_xlfn.STDEV.S('METCM (Meteomatics)'!J178) -> #DIV/0! | N23: =_xlfn.STDEV.S('METCM (Meteomatics)'!K178) -> #DIV/0!
H24: Median | I24: =MEDIAN('METCM (Meteomatics)'!J175) -> 269.05438 | J24: =MEDIAN('METCM (Meteomatics)'!K175) -> 36.587892 | K24: =MEDIAN('METCM (Meteomatics)'!J171) -> 251.67017 | L24: =MEDIAN('METCM (Meteomatics)'!K171) -> 37.273779 | M24: =MEDIAN('METCM (Meteomatics)'!J178) -> 280.92532 | N24: =MEDIAN('METCM (Meteomatics)'!K178) -> 36.845505
H25: Q1 | I25: =_xlfn.QUARTILE.INC(('METCM (Meteomatics)'!J175),1) -> 269.05438 | J25: =_xlfn.QUARTILE.INC(('METCM (Meteomatics)'!K175),1) -> 36.587892 | K25: =_xlfn.QUARTILE.INC(('METCM (Meteomatics)'!J171),1) -> 251.67017 | L25: =_xlfn.QUARTILE.INC(('METCM (Meteomatics)'!K171),1) -> 37.273779 | M25: =_xlfn.QUARTILE.INC(('METCM (Meteomatics)'!J178),1) -> 280.92532 | N25: =_xlfn.QUARTILE.INC(('METCM (Meteomatics)'!K178),1) -> 36.845505
H26: Q3 | I26: =_xlfn.QUARTILE.INC(('METCM (Meteomatics)'!J175),3) -> 269.05438 | J26: =_xlfn.QUARTILE.INC(('METCM (Meteomatics)'!K175),3) -> 36.587892 | K26: =_xlfn.QUARTILE.INC(('METCM (Meteomatics)'!J171),3) -> 251.67017 | L26: =_xlfn.QUARTILE.INC(('METCM (Meteomatics)'!K171),3) -> 37.273779 | M26: =_xlfn.QUARTILE.INC(('METCM (Meteomatics)'!J178),3) -> 280.92532 | N26: =_xlfn.QUARTILE.INC(('METCM (Meteomatics)'!K178),3) -> 36.845505
H27: IQR | I27: =I26-I25 -> 0 | J27: =J26-J25 -> 0 | K27: =K26-K25 -> 0 | L27: =L26-L25 -> 0 | M27: =M26-M25 -> 0 | N27: =N26-N25 -> 0
H28: 95% KI - nedre | I28: =I22-_xlfn.CONFIDENCE.T(0.05,I23,I21) -> #DIV/0! | J28: =J22-_xlfn.CONFIDENCE.T(0.05,J23,J21) -> #DIV/0! | K28: =K22-_xlfn.CONFIDENCE.T(0.05,K23,K21) -> #DIV/0! | L28: =L22-_xlfn.CONFIDENCE.T(0.05,L23,L21) -> #DIV/0! | M28: =M22-_xlfn.CONFIDENCE.T(0.05,M23,M21) -> #DIV/0! | N28: =N22-_xlfn.CONFIDENCE.T(0.05,N23,N21) -> #DIV/0!
H29: 95% KI - øvre | I29: =I22+_xlfn.CONFIDENCE.T(0.05,I23,I21) -> #DIV/0! | J29: =J22+_xlfn.CONFIDENCE.T(0.05,J23,J21) -> #DIV/0! | K29: =K22+_xlfn.CONFIDENCE.T(0.05,K23,K21) -> #DIV/0! | L29: =L22+_xlfn.CONFIDENCE.T(0.05,L23,L21) -> #DIV/0! | M29: =M22+_xlfn.CONFIDENCE.T(0.05,M23,M21) -> #DIV/0! | N29: =N22+_xlfn.CONFIDENCE.T(0.05,N23,N21) -> #DIV/0!
B30: Firing pos. Andøya | C30: CM pos. Andøya | D30: METCM | E30: AA0001 | F30: 09-23. APR 26 | G30: 5000 | H30: n (antall) | I30: =COUNT('METCM (Meteomatics)'!J129,'METCM (Meteomatics)'!J138,'METCM (Meteomatics)'!J147,'METCM (Meteomatics)'!J156) -> 4 | J30: =COUNT('METCM (Meteomatics)'!K129,'METCM (Meteomatics)'!K138,'METCM (Meteomatics)'!K147,'METCM (Meteomatics)'!K156) -> 4 | K30: =COUNT('METCM (Meteomatics)'!J130,'METCM (Meteomatics)'!J139,'METCM (Meteomatics)'!J148,'METCM (Meteomatics)'!J157) -> 4 | L30: =COUNT('METCM (Meteomatics)'!K130,'METCM (Meteomatics)'!K139,'METCM (Meteomatics)'!K148,'METCM (Meteomatics)'!K157) -> 4 | M30: =COUNT('METCM (Meteomatics)'!J131,'METCM (Meteomatics)'!J140,'METCM (Meteomatics)'!J149,'METCM (Meteomatics)'!J158) -> 4 | N30: =COUNT('METCM (Meteomatics)'!K131,'METCM (Meteomatics)'!K140,'METCM (Meteomatics)'!K149,'METCM (Meteomatics)'!K158) -> 4
H31: Gjennomsnitt | I31: =AVERAGE('METCM (Meteomatics)'!J129,'METCM (Meteomatics)'!J138,'METCM (Meteomatics)'!J147,'METCM (Meteomatics)'!J156) -> 64.062204 | J31: =AVERAGE('METCM (Meteomatics)'!K129,'METCM (Meteomatics)'!K138,'METCM (Meteomatics)'!K147,'METCM (Meteomatics)'!K156) -> 20.733349 | K31: =AVERAGE('METCM (Meteomatics)'!J130,'METCM (Meteomatics)'!J139,'METCM (Meteomatics)'!J148,'METCM (Meteomatics)'!J157) -> 65.105205 | L31: =AVERAGE('METCM (Meteomatics)'!K130,'METCM (Meteomatics)'!K139,'METCM (Meteomatics)'!K148,'METCM (Meteomatics)'!K157) -> 20.737189 | M31: =AVERAGE('METCM (Meteomatics)'!J131,'METCM (Meteomatics)'!J140,'METCM (Meteomatics)'!J149,'METCM (Meteomatics)'!J158) -> 68.310087 | N31: =AVERAGE('METCM (Meteomatics)'!K131,'METCM (Meteomatics)'!K140,'METCM (Meteomatics)'!K149,'METCM (Meteomatics)'!K158) -> 20.74964
H32: Standardavvik (utvalg) | I32: =_xlfn.STDEV.S('METCM (Meteomatics)'!J129,'METCM (Meteomatics)'!J138,'METCM (Meteomatics)'!J147,'METCM (Meteomatics)'!J156) -> 21.755507 | J32: =_xlfn.STDEV.S('METCM (Meteomatics)'!K129,'METCM (Meteomatics)'!K138,'METCM (Meteomatics)'!K147,'METCM (Meteomatics)'!K156) -> 0.14524618 | K32: =_xlfn.STDEV.S('METCM (Meteomatics)'!J130,'METCM (Meteomatics)'!J139,'METCM (Meteomatics)'!J148,'METCM (Meteomatics)'!J157) -> 21.084428 | L32: =_xlfn.STDEV.S('METCM (Meteomatics)'!K130,'METCM (Meteomatics)'!K139,'METCM (Meteomatics)'!K148,'METCM (Meteomatics)'!K157) -> 0.14281812 | M32: =_xlfn.STDEV.S('METCM (Meteomatics)'!J131,'METCM (Meteomatics)'!J140,'METCM (Meteomatics)'!J149,'METCM (Meteomatics)'!J158) -> 19.289937 | N32: =_xlfn.STDEV.S('METCM (Meteomatics)'!K131,'METCM (Meteomatics)'!K140,'METCM (Meteomatics)'!K149,'METCM (Meteomatics)'!K158) -> 0.13574038
H33: Median | I33: =MEDIAN('METCM (Meteomatics)'!J129,'METCM (Meteomatics)'!J138,'METCM (Meteomatics)'!J147,'METCM (Meteomatics)'!J156) -> 54.298051 | J33: =MEDIAN('METCM (Meteomatics)'!K129,'METCM (Meteomatics)'!K138,'METCM (Meteomatics)'!K147,'METCM (Meteomatics)'!K156) -> 20.676596 | K33: =MEDIAN('METCM (Meteomatics)'!J130,'METCM (Meteomatics)'!J139,'METCM (Meteomatics)'!J148,'METCM (Meteomatics)'!J157) -> 55.187722 | L33: =MEDIAN('METCM (Meteomatics)'!K130,'METCM (Meteomatics)'!K139,'METCM (Meteomatics)'!K148,'METCM (Meteomatics)'!K157) -> 20.680176 | M33: =MEDIAN('METCM (Meteomatics)'!J131,'METCM (Meteomatics)'!J140,'METCM (Meteomatics)'!J149,'METCM (Meteomatics)'!J158) -> 59.084114 | N33: =MEDIAN('METCM (Meteomatics)'!K131,'METCM (Meteomatics)'!K140,'METCM (Meteomatics)'!K149,'METCM (Meteomatics)'!K158) -> 20.693234
H34: Q1 | I34: =_xlfn.QUARTILE.INC(('METCM (Meteomatics)'!J129,'METCM (Meteomatics)'!J138,'METCM (Meteomatics)'!J147,'METCM (Meteomatics)'!J156),1) -> 51.744757 | J34: =_xlfn.QUARTILE.INC(('METCM (Meteomatics)'!K129,'METCM (Meteomatics)'!K138,'METCM (Meteomatics)'!K147,'METCM (Meteomatics)'!K156),1) -> 20.638861 | K34: =_xlfn.QUARTILE.INC(('METCM (Meteomatics)'!J130,'METCM (Meteomatics)'!J139,'METCM (Meteomatics)'!J148,'METCM (Meteomatics)'!J157),1) -> 53.459353 | L34: =_xlfn.QUARTILE.INC(('METCM (Meteomatics)'!K130,'METCM (Meteomatics)'!K139,'METCM (Meteomatics)'!K148,'METCM (Meteomatics)'!K157),1) -> 20.644764 | M34: =_xlfn.QUARTILE.INC(('METCM (Meteomatics)'!J131,'METCM (Meteomatics)'!J140,'METCM (Meteomatics)'!J149,'METCM (Meteomatics)'!J158),1) -> 58.213812 | N34: =_xlfn.QUARTILE.INC(('METCM (Meteomatics)'!K131,'METCM (Meteomatics)'!K140,'METCM (Meteomatics)'!K149,'METCM (Meteomatics)'!K158),1) -> 20.664321
H35: Q3 | I35: =_xlfn.QUARTILE.INC(('METCM (Meteomatics)'!J129,'METCM (Meteomatics)'!J138,'METCM (Meteomatics)'!J147,'METCM (Meteomatics)'!J156),3) -> 66.615499 | J35: =_xlfn.QUARTILE.INC(('METCM (Meteomatics)'!K129,'METCM (Meteomatics)'!K138,'METCM (Meteomatics)'!K147,'METCM (Meteomatics)'!K156),3) -> 20.771083 | K35: =_xlfn.QUARTILE.INC(('METCM (Meteomatics)'!J130,'METCM (Meteomatics)'!J139,'METCM (Meteomatics)'!J148,'METCM (Meteomatics)'!J157),3) -> 66.833575 | L35: =_xlfn.QUARTILE.INC(('METCM (Meteomatics)'!K130,'METCM (Meteomatics)'!K139,'METCM (Meteomatics)'!K148,'METCM (Meteomatics)'!K157),3) -> 20.772601 | M35: =_xlfn.QUARTILE.INC(('METCM (Meteomatics)'!J131,'METCM (Meteomatics)'!J140,'METCM (Meteomatics)'!J149,'METCM (Meteomatics)'!J158),3) -> 69.180389 | N35: =_xlfn.QUARTILE.INC(('METCM (Meteomatics)'!K131,'METCM (Meteomatics)'!K140,'METCM (Meteomatics)'!K149,'METCM (Meteomatics)'!K158),3) -> 20.778553
H36: IQR | I36: =I35-I34 -> 14.870742 | J36: =J35-J34 -> 0.13222175 | K36: =K35-K34 -> 13.374222 | L36: =L35-L34 -> 0.127837 | M36: =M35-M34 -> 10.966577 | N36: =N35-N34 -> 0.11423175
H37: 95% KI - nedre | I37: =I31-_xlfn.CONFIDENCE.T(0.05,I32,I30) -> 29.444337 | J37: =J31-_xlfn.CONFIDENCE.T(0.05,J32,J30) -> 20.50223 | K37: =K31-_xlfn.CONFIDENCE.T(0.05,K32,K30) -> 31.555175 | L37: =L31-_xlfn.CONFIDENCE.T(0.05,L32,L30) -> 20.509934 | M37: =M31-_xlfn.CONFIDENCE.T(0.05,M32,M30) -> 37.615492 | N37: =N31-_xlfn.CONFIDENCE.T(0.05,N32,N30) -> 20.533647
G38: 3000 | H38: 95% KI - øvre | I38: =I31+_xlfn.CONFIDENCE.T(0.05,I32,I30) -> 98.680071 | J38: =J31+_xlfn.CONFIDENCE.T(0.05,J32,J30) -> 20.964468 | K38: =K31+_xlfn.CONFIDENCE.T(0.05,K32,K30) -> 98.655235 | L38: =L31+_xlfn.CONFIDENCE.T(0.05,L32,L30) -> 20.964444 | M38: =M31+_xlfn.CONFIDENCE.T(0.05,M32,M30) -> 99.004682 | N38: =N31+_xlfn.CONFIDENCE.T(0.05,N32,N30) -> 20.965633
E39: AA0002 | H39: n (antall) | I39: =COUNT('METCM (Meteomatics)'!J132,'METCM (Meteomatics)'!J141,'METCM (Meteomatics)'!J150,'METCM (Meteomatics)'!J159) -> 4 | J39: =COUNT('METCM (Meteomatics)'!K132,'METCM (Meteomatics)'!K141,'METCM (Meteomatics)'!K150,'METCM (Meteomatics)'!K159) -> 4 | K39: =COUNT('METCM (Meteomatics)'!J133,'METCM (Meteomatics)'!J142,'METCM (Meteomatics)'!J151,'METCM (Meteomatics)'!J160) -> 4 | L39: =COUNT('METCM (Meteomatics)'!K133,'METCM (Meteomatics)'!K142,'METCM (Meteomatics)'!K151,'METCM (Meteomatics)'!K160) -> 4 | M39: =COUNT('METCM (Meteomatics)'!J134,'METCM (Meteomatics)'!J143,'METCM (Meteomatics)'!J152,'METCM (Meteomatics)'!J161) -> 4 | N39: =COUNT('METCM (Meteomatics)'!K134,'METCM (Meteomatics)'!K143,'METCM (Meteomatics)'!K152,'METCM (Meteomatics)'!K161) -> 4
H40: Gjennomsnitt | I40: =AVERAGE('METCM (Meteomatics)'!J132,'METCM (Meteomatics)'!J141,'METCM (Meteomatics)'!J150,'METCM (Meteomatics)'!J159) -> 182.55671 | J40: =AVERAGE('METCM (Meteomatics)'!K132,'METCM (Meteomatics)'!K141,'METCM (Meteomatics)'!K150,'METCM (Meteomatics)'!K159) -> 28.084126 | K40: =AVERAGE('METCM (Meteomatics)'!J133,'METCM (Meteomatics)'!J142,'METCM (Meteomatics)'!J151,'METCM (Meteomatics)'!J160) -> 187.33712 | L40: =AVERAGE('METCM (Meteomatics)'!K133,'METCM (Meteomatics)'!K142,'METCM (Meteomatics)'!K151,'METCM (Meteomatics)'!K160) -> 28.118152 | M40: =AVERAGE('METCM (Meteomatics)'!J134,'METCM (Meteomatics)'!J143,'METCM (Meteomatics)'!J152,'METCM (Meteomatics)'!J161) -> 202.2321 | N40: =AVERAGE('METCM (Meteomatics)'!K134,'METCM (Meteomatics)'!K143,'METCM (Meteomatics)'!K152,'METCM (Meteomatics)'!K161) -> 28.227116
...
